Traceback (most recent call last):
  File "/home/calvin/Documents/projects/github/openmodelingfoundation/meillionen/.venv/lib/python3.8/site-packages/jupyter_cache/executors/utils.py", line 51, in single_nb_execution
    executenb(
  File "/home/calvin/Documents/projects/github/openmodelingfoundation/meillionen/.venv/lib/python3.8/site-packages/nbclient/client.py", line 1112, in execute
    return NotebookClient(nb=nb, resources=resources, km=km, **kwargs).execute()
  File "/home/calvin/Documents/projects/github/openmodelingfoundation/meillionen/.venv/lib/python3.8/site-packages/nbclient/util.py", line 74, in wrapped
    return just_run(coro(*args, **kwargs))
  File "/home/calvin/Documents/projects/github/openmodelingfoundation/meillionen/.venv/lib/python3.8/site-packages/nbclient/util.py", line 53, in just_run
    return loop.run_until_complete(coro)
  File "/usr/lib/python3.8/asyncio/base_events.py", line 616, in run_until_complete
    return future.result()
  File "/home/calvin/Documents/projects/github/openmodelingfoundation/meillionen/.venv/lib/python3.8/site-packages/nbclient/client.py", line 553, in async_execute
    await self.async_execute_cell(
  File "/home/calvin/Documents/projects/github/openmodelingfoundation/meillionen/.venv/lib/python3.8/site-packages/nbclient/client.py", line 857, in async_execute_cell
    self._check_raise_for_error(cell, exec_reply)
  File "/home/calvin/Documents/projects/github/openmodelingfoundation/meillionen/.venv/lib/python3.8/site-packages/nbclient/client.py", line 760, in _check_raise_for_error
    raise CellExecutionError.from_cell_and_msg(cell, exec_reply_content)
nbclient.exceptions.CellExecutionError: An error occurred while executing the following cell:
------------------
run_simple_crop(fr)
------------------

[0;31m---------------------------------------------------------------------------[0m
[0;31mOSError[0m                                   Traceback (most recent call last)
[0;32m<ipython-input-3-39de43110ff0>[0m in [0;36m<module>[0;34m[0m
[0;32m----> 1[0;31m [0mrun_simple_crop[0m[0;34m([0m[0mfr[0m[0;34m)[0m[0;34m[0m[0;34m[0m[0m
[0m
[0;32m~/Documents/projects/github/openmodelingfoundation/meillionen/.venv/lib/python3.8/site-packages/meillionen/client.py[0m in [0;36m__call__[0;34m(self, fr)[0m
[1;32m     16[0m [0;34m[0m[0m
[1;32m     17[0m     [0;32mdef[0m [0m__call__[0m[0;34m([0m[0mself[0m[0;34m,[0m [0mfr[0m[0;34m)[0m[0;34m:[0m[0;34m[0m[0;34m[0m[0m
[0;32m---> 18[0;31m         [0mself[0m[0;34m.[0m[0minterface[0m[0;34m.[0m[0mcall_cli[0m[0;34m([0m[0mself[0m[0;34m.[0m[0mpath[0m[0;34m,[0m [0mfr[0m[0;34m)[0m[0;34m[0m[0;34m[0m[0m
[0m
[0;31mOSError[0m: 
Stdout:


Stderr:
Traceback (most recent call last):
  File "/home/calvin/Documents/projects/github/openmodelingfoundation/meillionen/.venv/bin/simplecrop", line 8, in <module>
    sys.exit(run_cli())
  File "/home/calvin/Documents/projects/github/openmodelingfoundation/meillionen/.venv/lib/python3.8/site-packages/simplecrop_cli/__init__.py", line 38, in run_cli
    yearly: pd.DataFrame = PandasLoader.load(args.get_source('yearly'))
  File "/home/calvin/Documents/projects/github/openmodelingfoundation/meillionen/.venv/lib/python3.8/site-packages/meillionen/io.py", line 80, in load
    return _PANDAS_LOADER[source['type']](source)
  File "/home/calvin/Documents/projects/github/openmodelingfoundation/meillionen/.venv/lib/python3.8/site-packages/meillionen/io.py", line 71, in _load_feather
    return pd.read_feather(source['path'])
  File "/home/calvin/Documents/projects/github/openmodelingfoundation/meillionen/.venv/lib/python3.8/site-packages/pandas/io/feather_format.py", line 123, in read_feather
    with get_handle(
  File "/home/calvin/Documents/projects/github/openmodelingfoundation/meillionen/.venv/lib/python3.8/site-packages/pandas/io/common.py", line 651, in get_handle
    handle = open(handle, ioargs.mode)
FileNotFoundError: [Errno 2] No such file or directory: '../examples/crop-pipeline/simplecrop/data/yearly.feather'

OSError: 
Stdout:


Stderr:
Traceback (most recent call last):
  File "/home/calvin/Documents/projects/github/openmodelingfoundation/meillionen/.venv/bin/simplecrop", line 8, in <module>
    sys.exit(run_cli())
  File "/home/calvin/Documents/projects/github/openmodelingfoundation/meillionen/.venv/lib/python3.8/site-packages/simplecrop_cli/__init__.py", line 38, in run_cli
    yearly: pd.DataFrame = PandasLoader.load(args.get_source('yearly'))
  File "/home/calvin/Documents/projects/github/openmodelingfoundation/meillionen/.venv/lib/python3.8/site-packages/meillionen/io.py", line 80, in load
    return _PANDAS_LOADER[source['type']](source)
  File "/home/calvin/Documents/projects/github/openmodelingfoundation/meillionen/.venv/lib/python3.8/site-packages/meillionen/io.py", line 71, in _load_feather
    return pd.read_feather(source['path'])
  File "/home/calvin/Documents/projects/github/openmodelingfoundation/meillionen/.venv/lib/python3.8/site-packages/pandas/io/feather_format.py", line 123, in read_feather
    with get_handle(
  File "/home/calvin/Documents/projects/github/openmodelingfoundation/meillionen/.venv/lib/python3.8/site-packages/pandas/io/common.py", line 651, in get_handle
    handle = open(handle, ioargs.mode)
FileNotFoundError: [Errno 2] No such file or directory: '../examples/crop-pipeline/simplecrop/data/yearly.feather'


